Workbook

Sheet Dashboard 26
I1: Mensal do mês atual | K1: =CONCATENATE("0", MONTH(TODAY()), "/", RIGHT(YEAR(TODAY()), 2)) -> 06/26
H2: 1 - | I2: =IFERROR(__xludf.DUMMYFUNCTION("QUERY('2026'!A:D,""SELECT A WHERE D = 'Mensal' AND C='""&K1&""'"", FALSE)"),"#N/A") -> #N/A | J2: ✅
H3: 2 - | J3: ✅
H4: 3 - | J4: ✅
H5: 4 - | J5: ✅
H6: 5 - | J6: ✅
H7: 6 - | J7: ✅
H8: 7 - | J8: ✅
H9: 8 - | J9: ✅
H10: 9 - | J10: ✅
H11: 10 - | J11: ✅
H12: 11 - | J12: ✅
H13: 12 - | J13: ✅
H14: 13 - | J14: ✅
H15: 14 - | J15: ✅
J16: ✅

Sheet 2026
A1: Nome | B1: Valor | C1: Mes | D1: Tipo | E1: Tipo
A2: Roger | B2: 75 | C2: 01/26 | D2: =VLOOKUP(B2,Dictionary!A:B,2,FALSE) -> Mensal
A3: Breno | B3: 25 | C3: 01/26 | D3: =VLOOKUP(B3,Dictionary!A:B,2,FALSE) -> Avulso
A4: Filipinho | B4: 75 | C4: 01/26 | D4: =VLOOKUP(B4,Dictionary!A:B,2,FALSE) -> Mensal
A5: Vitor | B5: 75 | C5: 01/26 | D5: =VLOOKUP(B5,Dictionary!A:B,2,FALSE) -> Mensal
A6: Quadra | B6: -960 | C6: 01/26 | D6: =VLOOKUP(B6,Dictionary!A:B,2,FALSE) -> Quadra 2026 - 4 JOGOS
A7: Binho | B7: 25 | C7: 01/26 | D7: =VLOOKUP(B7,Dictionary!A:B,2,FALSE) -> Avulso
A8: Binho | B8: 25 | C8: 01/26 | D8: =VLOOKUP(B8,Dictionary!A:B,2,FALSE) -> Avulso
A9: Murilo | B9: 75 | C9: 01/26 | D9: =VLOOKUP(B9,Dictionary!A:B,2,FALSE) -> Mensal
A10: Gui | B10: 75 | C10: 01/26 | D10: =VLOOKUP(B10,Dictionary!A:B,2,FALSE) -> Mensal
A11: Raulnir | B11: 75 | C11: 01/26 | D11: =VLOOKUP(B11,Dictionary!A:B,2,FALSE) -> Mensal
A12: Tales | B12: 75 | C12: 01/26 | D12: =VLOOKUP(B12,Dictionary!A:B,2,FALSE) -> Mensal
A13: Caveira | B13: 75 | C13: 01/26 | D13: =VLOOKUP(B13,Dictionary!A:B,2,FALSE) -> Mensal
... A31: Gui | B31: 60 | C31: 02/26 | D31: =VLOOKUP(B31,Dictionary!A:B,2,FALSE) -> Mensal
A32: Samoel | B32: 60 | C32: 02/26 | D32: =IFNA(VLOOKUP(B32,Dictionary!A:B,2,FALSE),"") -> Mensal
A33: Bita | B33: 60 | C33: 02/26 | D33: =IFNA(VLOOKUP(B33,Dictionary!A:B,2,FALSE),"") -> Mensal
A34: Cod | B34: 20 | C34: 02/26 | D34: =IFNA(VLOOKUP(B34,Dictionary!A:B,2,FALSE),"") -> Avulso antigo
A35: Leandro | B35: 25 | C35: 02/26 | D35: =IFNA(VLOOKUP(B35,Dictionary!A:B,2,FALSE),"") -> Avulso
A36: Tio Zé | B36: 25 | C36: 02/26 | D36: =IFNA(VLOOKUP(B36,Dictionary!A:B,2,FALSE),"") -> Avulso
A37: Filipinho | B37: 25 | C37: 02/26 | D37: =IFNA(VLOOKUP(B37,Dictionary!A:B,2,FALSE),"") -> Avulso
A38: Marcelo | B38: 25 | C38: 02/26 | D38: =IFNA(VLOOKUP(B38,Dictionary!A:B,2,FALSE),"") -> Avulso
A39: Murilo | B39: 80 | C39: 03/26 | D39: =IFNA(VLOOKUP(B39,Dictionary!A:B,2,FALSE),"") -> Mensal
A40: Gui | B40: 80 | C40: 03/26 | D40: =IFNA(VLOOKUP(B40,Dictionary!A:B,2,FALSE),"") -> Mensal
A41: Sartor | B41: 80 | C41: 03/26 | D41: =IFNA(VLOOKUP(B41,Dictionary!A:B,2,FALSE),"") -> Mensal
A42: Roger | B42: 80 | C42: 03/26 | D42: =IFNA(VLOOKUP(B42,Dictionary!A:B,2,FALSE),"") -> Mensal
A43: Vitor | B43: 60 | C43: 03/26 | D43: =IFNA(VLOOKUP(B43,Dictionary!A:B,2,FALSE),"") -> Mensal
... A83: Tales | B83: 25 | C83: 04/26 | D83: =IFNA(VLOOKUP(B83,Dictionary!A:B,2,FALSE),"") -> Avulso
A84: Moha | C84: 04/26 | D84: =IFNA(VLOOKUP(B84,Dictionary!A:B,2,FALSE),"")
A85: Valdo | B85: 25 | C85: 04/26 | D85: =IFNA(VLOOKUP(B85,Dictionary!A:B,2,FALSE),"") -> Avulso
A86: Manu | B86: 25 | C86: 04/26 | D86: =IFNA(VLOOKUP(B86,Dictionary!A:B,2,FALSE),"") -> Avulso
A87: Bita | B87: 25 | C87: 04/26 | D87: =IFNA(VLOOKUP(B87,Dictionary!A:B,2,FALSE),"") -> Avulso
A88: Breno | B88: 25 | C88: 04/26 | D88: =IFNA(VLOOKUP(B88,Dictionary!A:B,2,FALSE),"") -> Avulso
A89: Theo | B89: 25 | C89: 04/26 | D89: =IFNA(VLOOKUP(B89,Dictionary!A:B,2,FALSE),"") -> Avulso
A90: Tales | B90: 25 | C90: 04/26 | D90: =IFNA(VLOOKUP(B90,Dictionary!A:B,2,FALSE),"") -> Avulso
A91: Bita | B91: 25 | C91: 04/26 | D91: =IFNA(VLOOKUP(B91,Dictionary!A:B,2,FALSE),"") -> Avulso
A92: Israel | B92: 25 | C92: 04/26 | D92: =IFNA(VLOOKUP(B92,Dictionary!A:B,2,FALSE),"") -> Avulso
A93: Binho | B93: 25 | C93: 04/26 | D93: =IFNA(VLOOKUP(B93,Dictionary!A:B,2,FALSE),"") -> Avulso
A94: Breno | B94: 25 | C94: 04/26 | D94: =IFNA(VLOOKUP(B94,Dictionary!A:B,2,FALSE),"") -> Avulso
A95: Cleber | B95: 25 | C95: 04/26 | D95: =IFNA(VLOOKUP(B95,Dictionary!A:B,2,FALSE),"") -> Avulso
A96: Diogo | B96: -40 | C96: 04/26 | D96: =IFNA(VLOOKUP(B96,Dictionary!A:B,2,FALSE),"") -> Goleiro App
...

Sheet 2025
A1: Nome | B1: Valor | C1: Mes | D1: Tipo | E1: Tipo
A2: Matheuszinho | B2: 60 | C2: 01/25 | D2: =VLOOKUP(B2,Dictionary!A:B,2,FALSE) -> Mensal
A3: Caveira | B3: 60 | C3: 01/25 | D3: =VLOOKUP(B3,Dictionary!A:B,2,FALSE) -> Mensal
A4: Carlos | B4: 25 | C4: 01/25 | D4: =VLOOKUP(B4,Dictionary!A:B,2,FALSE) -> Avulso
A5: Brandao | B5: 60 | C5: 01/25 | D5: =VLOOKUP(B5,Dictionary!A:B,2,FALSE) -> Mensal
A6: Tio Zé | B6: 25 | C6: 01/25 | D6: =VLOOKUP(B6,Dictionary!A:B,2,FALSE) -> Avulso
A7: Sartor | B7: 25 | C7: 01/25 | D7: =VLOOKUP(B7,Dictionary!A:B,2,FALSE) -> Avulso
A8: Marcelo Machado | B8: 60 | C8: 01/25 | D8: =VLOOKUP(B8,Dictionary!A:B,2,FALSE) -> Mensal
A9: Moha | B9: 25 | C9: 01/25 | D9: =VLOOKUP(B9,Dictionary!A:B,2,FALSE) -> Avulso
A10: Deucher | B10: 60 | C10: 01/25 | D10: =VLOOKUP(B10,Dictionary!A:B,2,FALSE) -> Mensal
A11: Erick | B11: 60 | C11: 01/25 | D11: =VLOOKUP(B11,Dictionary!A:B,2,FALSE) -> Mensal
A12: Tio Valdo | B12: 60 | C12: 01/25 | D12: =VLOOKUP(B12,Dictionary!A:B,2,FALSE) -> Mensal
A13: Roger | B13: 60 | C13: 01/25 | D13: =VLOOKUP(B13,Dictionary!A:B,2,FALSE) -> Mensal
... A63: Marcelo Machado | B63: 50 | C63: 03/25 | D63: =VLOOKUP(B63,Dictionary!A:B,2,FALSE) -> #N/A
A64: Quadra | B64: -690 | C64: 03/25 | D64: =VLOOKUP(B64,Dictionary!A:B,2,FALSE) -> Quadra 3 jogos | F64: quadra
A65: Camisa horário | B65: -240 | C65: 03/25 | D65: =VLOOKUP(B65,Dictionary!A:B,2,FALSE) -> Quadra 2026
A66: Tales | B66: 50 | C66: 03/25 | D66: =VLOOKUP(B66,Dictionary!A:B,2,FALSE) -> #N/A
A67: Vitor | B67: 50 | C67: 03/25 | D67: =VLOOKUP(B67,Dictionary!A:B,2,FALSE) -> #N/A
A68: Samuka | B68: 50 | C68: 03/25 | D68: =VLOOKUP(B68,Dictionary!A:B,2,FALSE) -> #N/A
A69: Tio Valdo | B69: 50 | C69: 03/25 | D69: =VLOOKUP(B69,Dictionary!A:B,2,FALSE) -> #N/A
A70: Matheuszinho | B70: 50 | C70: 03/25 | D70: =VLOOKUP(B70,Dictionary!A:B,2,FALSE) -> #N/A
A71: Goleiro (App) | B71: -33 | C71: 03/25 | D71: =VLOOKUP(B71,Dictionary!A:B,2,FALSE) -> #N/A
A72: Saldo Salchipão | B72: -35 | C72: 03/25 | D72: =VLOOKUP(B72,Dictionary!A:B,2,FALSE) -> #N/A
A73: Goleiro (App) | B73: -40 | C73: 03/25 | D73: =VLOOKUP(B73,Dictionary!A:B,2,FALSE) -> Goleiro App
A74: Murilo | B74: 75 | C74: 04/25 | D74: =VLOOKUP(B74,Dictionary!A:B,2,FALSE) -> Mensal
A75: Gui | B75: 75 | C75: 04/25 | D75: =VLOOKUP(B75,Dictionary!A:B,2,FALSE) -> Mensal
A76: Caveira | B76: 75 | C76: 04/25 | D76: =VLOOKUP(B76,Dictionary!A:B,2,FALSE) -> Mensal
... A220: Breno | B220: 25 | C220: 10/25 | D220: =VLOOKUP(B220,Dictionary!A:B,2,FALSE) -> Avulso
A221: Tio Zé | B221: 50 | C221: 10/25 | D221: Mensal
A222: Goleiro (App) | B222: -40 | C222: 10/25 | D222: =VLOOKUP(B222,Dictionary!A:B,2,FALSE) -> Goleiro App
A223: Goleiro (App) | B223: -40 | C223: 10/25 | D223: =VLOOKUP(B223,Dictionary!A:B,2,FALSE) -> Goleiro App
A224: Humberto | B224: 25 | C224: 10/25 | D224: =VLOOKUP(B224,Dictionary!A:B,2,FALSE) -> Avulso
A225: Cod | B225: 25 | C225: 10/25 | D225: =VLOOKUP(B225,Dictionary!A:B,2,FALSE) -> Avulso
A226: Samuca | B226: 25 | C226: 10/25 | D226: =VLOOKUP(B226,Dictionary!A:B,2,FALSE) -> Avulso
A227: Vinicius Santiago | B227: 25 | C227: 10/25 | D227: =VLOOKUP(B227,Dictionary!A:B,2,FALSE) -> Avulso
A228: Quadra | B228: -920 | C228: 10/25 | D228: =VLOOKUP(B228,Dictionary!A:B,2,FALSE) -> Quadra 4 jogos
A229: Murilo | B229: 75 | C229: 10/25 | D229: =VLOOKUP(B229,Dictionary!A:B,2,FALSE) -> Mensal
A230: Gui | B230: 75 | C230: 10/25 | D230: =VLOOKUP(B230,Dictionary!A:B,2,FALSE) -> Mensal
A231: Sartor | B231: 75 | C231: 10/25 | D231: =VLOOKUP(B231,Dictionary!A:B,2,FALSE) -> Mensal
A232: Marcao | B232: 75 | C232: 10/25 | D232: =VLOOKUP(B232,Dictionary!A:B,2,FALSE) -> Mensal
...

Sheet 2024
A1: Leandro Melo | B1: 75 | C1: 11/24 | E1: =if(B1>=60,"Mensal","Avulso") -> Mensal
A2: Leonardo Melo | B2: 75 | C2: 11/24 | E2: =if(B2>=60,"Mensal","Avulso") -> Mensal
A3: Gui | B3: 75 | C3: 11/24 | E3: =if(B3>=60,"Mensal","Avulso") -> Mensal
A4: Murilo | B4: 75 | C4: 11/24 | E4: =if(B4>=60,"Mensal","Avulso") -> Mensal
A5: Brandão | B5: 75 | C5: 11/24 | E5: =if(B5>=60,"Mensal","Avulso") -> Mensal
A6: Tio Zé | B6: 75 | C6: 11/24 | E6: =if(B6>=60,"Mensal","Avulso") -> Mensal
A7: Malcon | B7: 25 | C7: 11/24 | E7: =if(B7>=60,"Mensal","Avulso") -> Avulso
A8: Raulnir | B8: 75 | C8: 11/24 | E8: =if(B8>=60,"Mensal","Avulso") -> Mensal
A9: Tio Valdo | B9: 75 | C9: 11/24 | E9: =if(B9>=60,"Mensal","Avulso") -> Mensal
A10: Deparis | C10: 11/24 | E10: =if(B10>=60,"Mensal","Avulso") -> Avulso
A11: Leandrinho | B11: 75 | C11: 11/24 | E11: =if(B11>=60,"Mensal","Avulso") -> Mensal
A12: Roger | B12: 75 | C12: 11/24 | E12: =if(B12>=60,"Mensal","Avulso") -> Mensal
A13: Marquinhos | B13: 25 | C13: 11/24 | E13: =if(B13>=60,"Mensal","Avulso") -> Avulso
A14: Filipinho | B14: 75 | C14: 11/24 | E14: =if(B14>=60,"Mensal","Avulso") -> Mensal
A15: Matheuszinho | B15: 25 | C15: 11/24 | E15: =if(B15>=60,"Mensal","Avulso") -> Avulso
A16: Quadra | B16: -920 | C16: 11/24 | E16: =if(B16>=60,"Mensal","Avulso") -> Avulso
A17: Moha | B17: 25 | C17: 11/24 | E17: =if(B17>=60,"Mensal","Avulso") -> Avulso
A18: Pedrinho | B18: 25 | C18: 11/24 | E18: =if(B18>=60,"Mensal","Avulso") -> Avulso
A19: Matheuszinho | B19: 25 | C19: 11/24 | E19: =if(B19>=60,"Mensal","Avulso") -> Avulso
A20: Lucas (avulso) | B20: 25 | C20: 11/24 | E20: =if(B20>=60,"Mensal","Avulso") -> Avulso
A21: Matheuszinho | B21: 25 | C21: 11/24 | E21: =if(B21>=60,"Mensal","Avulso") -> Avulso
A22: Tales | B22: 25 | C22: 11/24 | E22: =if(B22>=60,"Mensal","Avulso") -> Avulso
... A31: Marquinhos | B31: 60 | C31: 12/24 | E31: =if(B31>=60,"Mensal","Avulso") -> Mensal
A32: Churras | B32: -120 | C32: 12/24
A33: Roger | B33: 60 | C33: 12/24 | E33: =if(B33>=60,"Mensal","Avulso") -> Mensal
A34: Ze | B34: 60 | C34: 12/24 | E34: =if(B34>=60,"Mensal","Avulso") -> Mensal
A35: Valdo | B35: 60 | C35: 12/24 | E35: =if(B35>=60,"Mensal","Avulso") -> Mensal
A36: Lenadrinho | B36: 60 | C36: 12/24 | E36: =if(B36>=60,"Mensal","Avulso") -> Mensal
A37: Quadra | B37: -690 | C37: 12/24 | E37: =if(B37>=60,"Mensal","Avulso") -> Avulso
A38: Leandro Melo | B38: 60 | C38: 12/24 | E38: =if(B38>=60,"Mensal","Avulso") -> Mensal
A39: Eduardo | B39: 25 | C39: 12/24 | E39: =if(B39>=60,"Mensal","Avulso") -> Avulso
A40: Brandão | B40: 25 | C40: 12/24 | E40: =if(B40>=60,"Mensal","Avulso") -> Avulso
A41: Filipinho | B41: 60 | C41: 12/24 | E41: =if(B41>=60,"Mensal","Avulso") -> Mensal
A42: Goleiro (App) | B42: -39 | C42: 12/24 | E42: =if(B42>=60,"Mensal","Avulso") -> Avulso
A43: Deparis | B43: 80 | C43: 12/24 | E43: =if(B43>=60,"Mensal","Avulso") -> Mensal
A44: Goleiro (App) | B44: -44 | C44: 12/24 | E44: =if(B44>=60,"Mensal","Avulso") -> Avulso
... A49: Matheuszinho | B49: 25 | C49: 12/24 | E49: =if(B49>=60,"Mensal","Avulso") -> Avulso

Sheet Camisas
A2: Gui | B2: 120 | C2: G | D2: As duas
A3: Raulnir | B3: 120 | C3: G
A4: Murilo | B4: 120 | C4: G | D4: As duas
A5: Brandão | B5: 120 | C5: M
A6: Filipinho | B6: 120 | C6: P
A7: Marcao | B7: 120 | C7: M | D7: As duas
A8: Deninho | B8: 120 | C8: G
A9: Caveira | B9: 120 | C9: GG
A10: Tio Zé | B10: 120 | C10: P | F10: Andrey | H10: Alex.
A11: Roger | B11: 120 | C11: G | F11: Caveira | G11: =VLOOKUP(F11,$A$1:$C$25,3,FALSE) -> GG | H11: Tales | I11: =VLOOKUP(H11,$A$1:$C$25,3,FALSE) -> G
A12: Leandro Melo | B12: 120 | C12: G | F12: Brandão | G12: =VLOOKUP(F12,$A$1:$C$25,3,FALSE) -> M | H12: Murilo | I12: =VLOOKUP(H12,$A$1:$C$25,3,FALSE) -> G
A13: Maurício | B13: 120 | C13: M | D13: Apenas uma | F13: Vitor | G13: =VLOOKUP(F13,$A$1:$C$25,3,FALSE) -> G | H13: Marcelo | I13: =VLOOKUP(H13,$A$1:$C$25,3,FALSE) -> M
A14: Marcelo | B14: 120 | C14: M | F14: Marcao | G14: =VLOOKUP(F14,$A$1:$C$25,3,FALSE) -> M | H14: Samoel | I14: =VLOOKUP(H14,$A$1:$C$25,3,FALSE) -> M
A15: Tio Valdo | B15: 120 | C15: M | F15: Tio Valdo | G15: =VLOOKUP(F15,$A$1:$C$25,3,FALSE) -> M | H15: Tio Zé | I15: =VLOOKUP(H15,$A$1:$C$25,3,FALSE) -> P
A16: Pai do Caveira | B16: 120 | C16: G | F16: Deninho | G16: =VLOOKUP(F16,$A$1:$C$25,3,FALSE) -> G | H16: Roger | I16: =VLOOKUP(H16,$A$1:$C$25,3,FALSE) -> G
A17: Horário | B17: 120 | C17: G | F17: Matheus | G17: =VLOOKUP(F17,$A$1:$C$25,3,FALSE) -> M | H17: Maurício | I17: =VLOOKUP(H17,$A$1:$C$25,3,FALSE) -> M
A18: Horário | B18: 120 | C18: G | F18: Gui | G18: =VLOOKUP(F18,$A$1:$C$25,3,FALSE) -> G | H18: Deparis | I18: =VLOOKUP(H18,$A$1:$C$25,3,FALSE) -> #N/A
A19: Vitor | B19: 120 | C19: G
A20: Tales | B20: 120 | C20: G
A21: Samoel | B21: 120 | C21: M | D21: As duas
A22: Matheus | B22: 120 | C22: M
A23: Erick | B23: 120 | C23: M
A24: Malcom | B24: 120 | C24: G
A25: Marcos Schmidt | B25: 120 | C25: G
A26: Leandrinho | C26: M
A27: Compra | B27: -2627

Sheet Eventos
A1: Pessoa | B1: Gasto | C1: Data | D1: Descrição
A2: Churrasqueira | B2: -60 | C2: 45717 | D2: Aluguel - Churrasqueira
A3: Carne | B3: -40 | C3: 45717 | D3: Pães - Salchipão
A4: Carne | B4: -175 | C4: 45717 | D4: Salsichões
A5: Samuka | B5: 20 | C5: 45718
A6: Tales | B6: 20 | C6: 45719
A7: Marcelo | B7: 20 | C7: 45720
A8: Tio Waldo | B8: 20 | C8: 45721
A9: Raulnir | B9: 20 | C9: 45722
A10: Tio Zé | B10: 20 | C10: 45723
A11: Deninho | B11: 20 | C11: 45724
A12: Marcao | B12: 20 | C12: 45725
A13: Fabiano | B13: 20 | C13: 45726
A14: Deucher | B14: 20 | C14: 45727
A15: Caveira | B15: 20 | C15: 45728
A16: Murilo | B16: 20 | C16: 45729
... A32: Bitta | B32: 40 | C32: 45962
C33: 45962

Sheet Dictionary
A1: Valores | B1: Tipo
A2: 75 | B2: Mensal
A3: 25 | B3: Avulso
A4: -920 | B4: Quadra 4 jogos
A5: -1100 | B5: Quadra 5 jogos
A6: 60 | B6: Mensal
A7: -40 | B7: Goleiro App
A8: -38 | B8: Goleiro App
A9: 20 | B9: Avulso antigo
A10: -30 | B10: Goleiro App (por fora)
A11: -690 | B11: Quadra 3 jogos
A12: -240 | B12: Quadra 2026
A13: =$A$12*C13 -> -480 | B13: =CONCATENATE($B$12, " - ", C13, " JOGOS") -> Quadra 2026 - 2 JOGOS | C13: 2
A14: =$A$12*C14 -> -720 | B14: =CONCATENATE($B$12, " - ", C14, " JOGOS") -> Quadra 2026 - 3 JOGOS | C14: 3
A15: =$A$12*C15 -> -960 | B15: =CONCATENATE($B$12, " - ", C15, " JOGOS") -> Quadra 2026 - 4 JOGOS | C15: 4
A16: 80 | B16: Mensal | C16: (Mensal 5 jogos)
A17: -1150 | B17: Quadra 2026 - 5 jogos
A18: 85 | B18: Mensal | C18: (Mensal 5 jogos)
A19: -45 | B19: Goleiro App

Sheet Dashboard 25
L1: Mensal do mês atual | N1: =CONCATENATE(MONTH(TODAY()), "/", RIGHT(YEAR(TODAY()), 2)) -> 6/26
L2: =IFERROR(__xludf.DUMMYFUNCTION("QUERY('2025'!A:D,""SELECT A WHERE D = 'Mensal' AND C='""&N1&""'"", FALSE)"),"#N/A") -> #N/A
